<?xml version="1.0"?>
<robot xmlns:xacro="http://www.ros.org/wiki/xacro"  >

    <xacro:include filename="inertial_macros.xacro"/>
    
    <material name="white">
        <color rgba="1 1 1 1"/>
    </material>

    <material name="orange">
         <color rgba="1 0.3 0.1 1"/>
    </material>

    <material name="blue">
        <color rgba="0.2 0.2 1 1"/>
    </material>

    <material name="black">
        <color rgba="0 0 0 1"/>
    </material>
    
    <!--BASE LINK -->
    
    <link name="base_link">

    </link>
    
    <!-- BASE_FOOTPRINT LINK -->

    <joint name="base_footprint_joint" type="fixed">
        <parent link="base_link"/>
        <child link="base_footprint"/>
        <origin xyz="0 0 0" rpy="0 0 0"/>
    </joint>

    <link name="base_footprint">
    </link>    

    <!-- CHASSIS LINK -->

    <joint name="chassis_joint" type="fixed">
        <parent link="base_link"/>
        <child link="chassis"/>
        <origin xyz="-0.1 0 0"/>
    </joint>
    
    <!-- CHASSIS LINK -->
    
    <link name="chassis">
        <visual>
            <origin xyz="0.3 0 0.15" rpy="0 0 0"/>
            <geometry>
                <box size="0.5 0.604 0.252"/>
            </geometry>
            <material name="white"/>
        </visual>
        <collision>
            <origin xyz="0.3 0 0.15" rpy="0 0 0"/>
            <geometry>
                <box size="0.5 0.604 0.252"/>
            </geometry>
            <material name="white"/>
        </collision>
        
        
    </link>
    
    <gazebo reference="chassis">
    	<material>Gazebo/White</material> 
    </gazebo>
    
    <!--LEFT WHEEL LINK -->
    
    <joint name="left_wheel_joint" type="continuous">
        <parent link="base_link"/>
        <child link="left_wheel"/>
        <origin xyz="0 0.345 0" rpy="-${pi/2} 0 0"/>
        <axis xyz="0 0 1"/>
    </joint>

    <link name="left_wheel">
        <visual>
            <geometry>
                <cylinder length="0.08" radius="0.1" />
            </geometry>
            <material name="blue"/>
        </visual>
        <collision>
            <geometry>
                <cylinder length="0.08" radius="0.1" />
            </geometry>
            <material name="blue"/>
        </collision>
        <xacro:inertial_cylinder mass="0.1" length="0.08" radius ="0.1">
            <origin xyz="0 0 0" rpy="0 0 0"/> 
        </xacro:inertial_cylinder>
    </link>
    
    <gazebo reference="left_wheel">
    	<material>Gazebo/Blue</material> 
    </gazebo>
    
    <!-- RIGHT WHEEL -->

    <joint name="right_wheel_joint" type="continuous">
        <parent link="base_link"/>
        <child link="right_wheel"/>
        <origin xyz="0 -0.345 0" rpy="${pi/2} 0 0"/>
        <axis xyz="0 0 -1"/>
    </joint>

    <link name="right_wheel">
        <visual>
            <geometry>
                <cylinder length="0.08" radius="0.1" />
            </geometry>
            <material name="blue"/>
        </visual>
        <collision>
            <geometry>
                <cylinder length="0.08" radius="0.1" />
            </geometry>
            <material name="blue"/>
        </collision>
        <xacro:inertial_cylinder mass="0.1" length="0.08" radius ="0.1">
            <origin xyz="0 0 0" rpy="0 0 0"/> 
        </xacro:inertial_cylinder>
    </link>
    
    <gazebo reference="right_wheel">
    	<material>Gazebo/Blue</material> 
    </gazebo>
    
    <!-- CASTER WHEEL -->

    <joint name="caster_wheel_left_joint" type="fixed">
        <parent link="chassis"/>
        <child link="caster_left_wheel"/>
        <origin xyz="0.385 0.184 0" rpy="0 0 0"/>
    </joint>

    <link name="caster_left_wheel">
        <visual>
            <geometry>
                <sphere radius="0.1" />
            </geometry>
            <material name="black"/>
        </visual>
        <collision>
            <geometry>
                <sphere radius="0.1" />
            </geometry>
            <material name="black"/>
        </collision>
        <xacro:inertial_sphere mass="0.1" radius ="0.1">
            <origin xyz="0 0 0" rpy="0 0 0"/> 
        </xacro:inertial_sphere>
    </link>
    
    <joint name="caster_wheel_right_joint" type="fixed">
        <parent link="chassis"/>
        <child link="caster_right_wheel"/>
        <origin xyz="0.385 -0.184 0" rpy="0 0 0"/>
    </joint>
    
    <gazebo reference="caster_left_wheel">
    	<material>Gazebo/Black</material> 
    	<mu1 value="0.002"/>
    	<mu2 value="0.002"/>
    </gazebo>

    <link name="caster_right_wheel">
        <visual>
            <geometry>
                <sphere radius="0.1" />
            </geometry>
            <material name="black"/>
        </visual>
        <collision>
            <geometry>
                <sphere radius="0.1" />
            </geometry>
            <material name="black"/>
        </collision>
        <xacro:inertial_sphere mass="0.1" radius ="0.1">
            <origin xyz="0 0 0" rpy="0 0 0"/> 
        </xacro:inertial_sphere>
    </link>
    
    <gazebo reference="caster_right_wheel">
    	<material>Gazebo/Black</material> 
    	<mu1 value="0.002"/>
    	<mu2 value="0.002"/>
    </gazebo>
    
</robot>
